<?xml version="1.0" ?>

<robot name="alita_left">

	<!-- Links -->
	<link name = "world"/> 

	<link name = "L0"> 
		<inertial>
			<mass value="3.952"/>
			<inertia ixx="0.102" ixy="2.45e-05" ixz="0.00713" iyy="0.0832" iyz="-0.00131" izz="0.0864"/>
			<origin xyz="0.006575 -0.160104 0"/>
		</inertial>
		<visual> 
			<geometry> <mesh filename="../meshes/Schunk/L0.dae"/> </geometry> 
		</visual> 
		<collision>
			<geometry> <mesh filename="../meshes/Schunk/L0.dae"/> </geometry> 
		</collision> 
	</link>

	<link name = "L1"> 
		<inertial>
			<mass value="3.952"/>
			<inertia ixx="0.102" ixy="2.45e-05" ixz="0.00713" iyy="0.0832" iyz="-0.00131" izz="0.0864"/>
			<origin xyz="0.006575 -0.160104 0"/>
		</inertial>
		<visual> 
			<geometry> <mesh filename="../meshes/Schunk/L1.dae"/> </geometry> 
		</visual> 
		<collision>
			<origin xyz="0.015 -0.080866 0.0"/> 
			<geometry> <box size="0.16 0.29367 0.13188"/> </geometry>
		</collision> 
	</link>

	<link name = "L2"> 
		<inertial>
			<mass value="3.925"/>
			<inertia ixx="0.102" ixy="2.45e-05" ixz="0.00713" iyy="0.0832" iyz="-0.00131" izz="0.0864"/>
			<origin xyz="0.006895 -0.006745 0"/>
		</inertial>
		<visual> 
			<geometry> <mesh filename="../meshes/Schunk/L2.dae"/> </geometry> 
		</visual> 
		<collision>
			<origin xyz="0.017042 -0.058309 0.0"/> 
			<geometry> <box size="0.14591 0.24658 0.13"/> </geometry> 
		</collision> 
	</link>

	<link name = "L3"> 
		<inertial>
			<mass value="2.373"/>
			<inertia ixx="0.102" ixy="2.45e-05" ixz="0.00713" iyy="0.0832" iyz="-0.00131" izz="0.0864"/>
			<origin xyz="0.006855 -0.138146 0"/>
		</inertial>
		<visual> 
			<geometry> <mesh filename="../meshes/Schunk/L3.dae"/> </geometry> 
		</visual> 
		<collision>
			<origin xyz="0.014000 -0.075113 0.0"/> 
			<geometry> <box size="0.13800 0.26217 0.11189"/> </geometry> 
		</collision> 
	</link>

	<link name = "L4"> 
		<inertial>
			<mass value="2.373"/>
			<inertia ixx="0.102" ixy="2.45e-05" ixz="0.00713" iyy="0.0832" iyz="-0.00131" izz="0.0864"/>
			<origin xyz="0.007691 -0.007366 0"/>
		</inertial>
		<visual> 
			<geometry> <mesh filename="../meshes/Schunk/L4.dae"/> </geometry> 
		</visual> 
		<collision>
			<origin xyz="0.018200 -0.052050 0.0"/> 
			<geometry> <box size="0.12960 0.2141 0.11"/> </geometry> 
		</collision> 
	</link>

	<link name = "L5"> 
		<inertial>
			<mass value="1.41334"/>
			<inertia ixx="0.102" ixy="2.45e-05" ixz="0.00713" iyy="0.0832" iyz="-0.00131" izz="0.0864"/>
			<origin xyz="0.006777 -0.109824 0"/>
		</inertial>
		<visual> 
			<geometry> <mesh filename="../meshes/Schunk/L5.dae"/> </geometry> 
		</visual> 
		<collision>
			<origin xyz="0.0145115 -0.0571105 0.0000425"/> 
			<geometry> <box size="0.117977 0.204179 0.089915"/> </geometry>
		</collision> 
	</link>

	<link name = "L6"> 
		<inertial>
			<mass value="2.64634"/>
			<inertia ixx="0.102" ixy="2.45e-05" ixz="0.00713" iyy="0.0832" iyz="-0.00131" izz="0.0864"/>
			<origin xyz="0.005684 -0.071438 0"/>
		</inertial>
		<visual> 
			<geometry> <mesh filename="../meshes/Schunk/L6.dae"/> </geometry> 
		</visual> 
		<collision>
			<origin xyz="0.0175015 -0.0481615 0.0"/> 
			<geometry> <box size="0.111977 0.185277 0.089"/> </geometry>
		</collision> 
	</link>

	<link name = "lGripper"> 
		<inertial>
			<mass value="2.3"/>
			<inertia ixx="0.102" ixy="2.45e-05" ixz="0.00713" iyy="0.0832" iyz="-0.00131" izz="0.0864"/>
			<origin xyz="0.008 0 0.065"/>
		</inertial>
		<visual> 
			<geometry> <mesh filename="../meshes/Schunk/SchunkGripper/L7.dae"/> </geometry> 
		</visual> 
		<collision> 
			<origin xyz="0.0 -0.0 0.028" rpy="0.0 0.0 1.5708"/> 
			<geometry> <box size="0.15 0.125 0.210"/> </geometry>
		</collision> 
	</link>

	<link name = "lFingerA">
		<inertial> 
			<mass value="0.0001"/> 
			<inertia ixx="1e-4" ixy="1e-4" ixz="1e-4" iyy="1e-4" iyz="1e-4" izz="1e-4"/>
		</inertial>
		<visual> 
			<geometry> <mesh filename="../meshes/Schunk/SchunkGripper/gripperPlate.dae"/> </geometry> 
		</visual> 
		<collision>
			<origin xyz="-0.032 -0.0035 -0.01185" rpy="0.0 0.0 1.5708"/> 
			<geometry> <box size="0.07 0.10 0.07"/> </geometry> 
		</collision> 
		<collision>
			<origin xyz="-0.072 -0.0035 0.002" rpy="1.05 0.0 1.5708"/> 
			<geometry> <box size="0.07 0.10 0.07"/> </geometry> 
		</collision> 
		<collision>
			<origin xyz="-0.0815 -0.0035 0.048" rpy="0.0 0.0 1.5708"/> 
			<geometry> <box size="0.07 0.10 0.07"/> </geometry> 
		</collision> 
	</link> 	

	<link name = "lFingerB">
		<inertial> 
			<mass value="0.0001"/> 
			<inertia ixx="1e-4" ixy="1e-4" ixz="1e-4" iyy="1e-4" iyz="1e-4" izz="1e-4"/>
		</inertial>
		<visual> 
			<geometry> <mesh filename="../meshes/Schunk/SchunkGripper/gripperPlate.dae"/> </geometry> 
		</visual> 
		<collision>
			<origin xyz="-0.032 -0.0035 -0.01185" rpy="0.0 0.0 1.5708"/> 
			<!-- <geometry> <box size="0.035 0.07 0.0366"/> </geometry> -->
			<geometry> <box size="0.07 0.10 0.07"/> </geometry> 
		</collision> 
		<collision>
			<origin xyz="-0.072 -0.0035 0.002" rpy="1.05 0.0 1.5708"/> 
			<!-- <geometry> <box size="0.035 0.07 0.0366"/> </geometry> -->
			<geometry> <box size="0.07 0.10 0.07"/> </geometry> 
		</collision> 
		<collision>
			<origin xyz="-0.0815 -0.0035 0.048" rpy="0.0 0.0 1.5708"/> 
			<!-- <geometry> <box size="0.035 0.07 0.0366"/> </geometry> -->
			<geometry> <box size="0.07 0.10 0.07"/> </geometry> 
		</collision> 
	</link> 	

	<!-- *********************-->
	<!-- JOINTS               -->
	<!-- *********************-->

	<!-- LJ0 -->
	<joint name="LJ0" type="floating" >
   		<origin  rpy="0 0 0" xyz="0 0 0" />
		<parent link="world" />
		<child link="L0" />
	</joint>

	<joint name="LJ1" type="revolute"> 
		<parent link="L0" /> 
		<child link="L1" />
		<origin xyz = "0.18 0.000 0" rpy="0 3.141592 -1.570796" />
		<axis xyz="0 -1 0" /> <limit effort="1000" lower="-4.7124" upper="4.7124" velocity="0.1" />
	</joint>

	<joint name="LJ2" type="revolute"> 
		<parent link="L1" /> 
		<child link="L2" />
		<origin xyz="0 0.0 0" rpy="3.141592 3.141592 0" />
		<axis xyz="-1 0 0" /> <limit effort="1000" lower="-2.094" upper="2.094" velocity="0.1" />
	</joint>

	<joint name="LJ3" type="revolute"> 
		<parent link="L2" /> 
		<child link="L3" />
		<origin xyz="0 -0.328 0" rpy="-3.141592 -3.141592 0" />
		<axis xyz="0 -1 0" /> <limit effort="1000" lower="-4.7124" upper="4.7124" velocity="0.1" />
	</joint>

	<joint name="LJ4" type="revolute"> 
		<parent link="L3" /> 
		<child link="L4" />
		<origin xyz="0 0 0" rpy="3.141592 3.141592 0" />
		<axis xyz="-1 0 0" /> <limit effort="1000" lower="-2.094" upper="2.094" velocity="0.1" />
	</joint>

	<joint name="LJ5" type="revolute"> 
		<parent link="L4" /> 
		<child link="L5" />
		<origin xyz="0 -0.2765 0" rpy="3.141592 3.141592 0" />
		<axis xyz="0 -1 0" /> <limit effort="1000" lower="-4.7124" upper="4.7124" velocity="0.1" />
	</joint>

	<joint name="LJ6" type="revolute"> 
		<parent link="L5" /> 
		<child link="L6" />
		<origin xyz="0 0.0 0" rpy="3.141592 3.141592 0" />
		<axis xyz="-1 0 0" /> <limit effort="1000" lower="-2.094" upper="2.094" velocity="0.1" />
	</joint>

	<!-- For some reason, I had to negate the axis to make sure the motor turns like the others -->
	<joint name="LJFT" type="revolute"> 
		<parent link="L6" /> 
		<child link="lGripper" />
		<origin xyz="0 -0.200 0" rpy="1.570796 3.141592 0" />
		<axis xyz="0 0 -1" /> <limit effort="1000" lower="-4.7124" upper="4.7124" velocity="0.1" />
	</joint>

	<joint name="LJFA" type="prismatic"> 
		<parent link="lGripper" /> 
		<child link="lFingerA" />
		<origin xyz="-0.05 0.00 0.127" rpy="3.1416 0.0 0.0" />
		<axis xyz="1 0 0" /> <limit effort="1000" lower="0.0" upper="0.030" velocity="0.1" />
	</joint>

	<joint name="LJFB" type="prismatic"> 
		<parent link="lGripper" /> 
		<child link="lFingerB" />
		<origin xyz="0.050 -0.00 0.127" rpy="0 3.1416 0.0" />
		<axis xyz="1 0 0" /> <limit effort="1000" lower="0.0" upper="0.030" velocity="0.1" />
	</joint>



</robot>
