<?xml version="1.0" ?>

<robot name="alita_hand">

	<!-- Links -->
	<link name = "world"/> 

	<link name = "alita_palm"> 
		<inertial>
			<mass value="2.3"/>
			<inertia ixx="0.102" ixy="2.45e-05" ixz="0.00713" iyy="0.0832" iyz="-0.00131" izz="0.0864"/>
			<origin xyz="0.008 0 0.065"/>
		</inertial>
		<visual> 
			<geometry> <mesh filename="../meshes/Schunk/SchunkGripper/L7.dae"/> </geometry> 
		</visual> 
		<collision> 
			<origin xyz="0.0 -0.0 0.028" rpy="0.0 0.0 1.5708"/> 
			<geometry> <box size="0.15 0.125 0.210"/> </geometry>
		</collision> 
	</link>

	<link name = "fingerA">
		<inertial> 
			<mass value="0.0001"/> 
			<inertia ixx="1e-4" ixy="1e-4" ixz="1e-4" iyy="1e-4" iyz="1e-4" izz="1e-4"/>
		</inertial>
		<visual> 
			<geometry> <mesh filename="../meshes/Schunk/SchunkGripper/gripperPlate.dae"/> </geometry> 
		</visual> 
		<collision>
			<geometry> <mesh filename="../meshes/Schunk/SchunkGripper/gripperPlate.dae"/> </geometry> 
		</collision> 
	</link> 	

	<link name = "fingerB">
		<inertial> 
			<mass value="0.0001"/> 
			<inertia ixx="1e-4" ixy="1e-4" ixz="1e-4" iyy="1e-4" iyz="1e-4" izz="1e-4"/>
		</inertial>
		<visual> 
			<geometry> <mesh filename="../meshes/Schunk/SchunkGripper/gripperPlate.dae"/> </geometry> 
		</visual> 
		<collision>
			<geometry> <mesh filename="../meshes/Schunk/SchunkGripper/gripperPlate.dae"/> </geometry> 
		</collision> 

	</link> 	

	<!-- *********************-->
	<!-- JOINTS               -->
	<!-- *********************-->


	<!-- For some reason, I had to negate the axis to make sure the motor turns like the others -->
	<joint name="LJFT" type="floating"> 
		<parent link="world" /> 
		<child link="alita_palm" />
		<origin xyz="0 0 0" rpy="0 0 0" />
	</joint>

	<joint name="LJFA" type="prismatic"> 
		<parent link="alita_palm" /> 
		<child link="fingerA" />
<!--		<origin xyz="0.0 0.00 0.127" rpy="3.1416 0.0 0.0" /> -->
		<origin xyz="0.02 0.00 0.127" rpy="0.0 3.1416 0.0" />
		<axis xyz="-1 0 0" /> <limit effort="1000" lower="0.0" upper="0.035" velocity="0.1" />
	</joint>

	<joint name="LJFB" type="prismatic"> 
		<parent link="alita_palm" /> 
		<child link="fingerB" />
		<origin xyz="-0.02 0.00 0.127" rpy="3.1416 0.0 0.0" />
		<axis xyz="-1 0 0" /> <limit effort="1000" lower="0.0" upper="0.035" velocity="0.1" />
	</joint>



</robot>
