<?xml version="1.0"?>

<robot name="baxter">

  <link name="world" />

  <!-- First part: Torso -->
  <link name="base">
  </link>

  <link name="torso">
    <visual>
      <origin rpy="0 0 0" xyz="0 0 0"/>
      <geometry>
        <mesh filename="/home/ana/Research/commonData/robots/baxter/meshes/torso/base_link.DAE"/>
      </geometry>
    </visual>
    <collision>
      <origin rpy="0 0 0" xyz="0 0 0"/>
      <geometry>
        <mesh filename="/home/ana/Research/commonData/robots/baxter/meshes/torso/base_link_collision.DAE"/>
      </geometry>
    </collision>
    <inertial>
      <origin rpy="0 0 0" xyz="0.000000 0.000000 0.000000"/>
      <mass value="35.336455"/>
      <inertia ixx="1.849155" ixy="-0.000354" ixz="-0.154188" iyy="1.662671" iyz="0.003292" izz="0.802239"/>
    </inertial>
  </link>


  <link name="pedestal">
    <visual>
      <origin rpy="0 0 0" xyz="0 0 0"/>
      <geometry>
        <mesh filename="/home/ana/Research/commonData/robots/baxter/meshes/base/PEDESTAL.DAE"/>
      </geometry>
      <material name="darkgray">
        <color rgba=".2 .2 .2 1"/>
      </material>
    </visual>
    <collision>
      <origin rpy="0 0 0" xyz="0 0 0"/>
      <geometry>
        <mesh filename="/home/ana/Research/commonData/robots/baxter/meshes/base/pedestal_link_collision.DAE"/>
      </geometry>
    </collision>
    <inertial>
      <origin rpy="0 0 0" xyz="0 0 0"/>
      <mass value="60.86397744"/>
      <inertia ixx="5.0635929" ixy="0.00103417" ixz="0.80199628" iyy="6.08689388" iyz="0.00105311" izz="4.96191932"/>
    </inertial>
  </link>


  <link name="head">
    <visual>
      <origin rpy="0 0 0" xyz="0 0 .00953"/>
      <geometry>
        <mesh filename="/home/ana/Research/commonData/robots/baxter/meshes/head/H0.DAE"/>
      </geometry>
      <material name="darkgray">
        <color rgba=".2 .2 .2 1"/>
      </material>
    </visual>
    <collision>
      <origin rpy="0 0 0" xyz="0.0 0 0.0"/>
      <geometry>
        <sphere radius="0.001"/>
      </geometry>
    </collision>
    <inertial>
      <origin rpy="0 0 0" xyz="0 0 0"/>
      <mass value="0.547767"/>
      <inertia ixx="0.004641" ixy="0.000159" ixz="0.000242" iyy="0.003295" iyz="-0.001324" izz="0.003415"/>
    </inertial>
  </link>

  <link name="screen">
    <visual>
      <origin rpy="0 -1.57079632679 0" xyz="0 -.00953 -.0347"/>
      <geometry>
        <mesh filename="/home/ana/Research/commonData/robots/baxter/meshes/head/H1_rotY90.dae"/>
      </geometry>
      <material name="darkred">
        <color rgba=".5 .1 .1 1"/>
      </material>
    </visual>
    <collision>
      <origin rpy="0 0 0" xyz="0.0 0 0.0"/>
      <geometry>
        <sphere radius="0.001"/>
      </geometry>
    </collision>
    <inertial>
      <origin rpy="0 0 0" xyz="0 0 0"/>
      <mass value="0.440171"/>
      <inertia ixx="0.004006" ixy="0.000230" ixz="0.000002" iyy="0.002800" iyz="0.000029" izz="0.001509"/>
    </inertial>
  </link>

  <link name="sonar_ring">
    <visual>
      <origin rpy="0 0 0" xyz="-.0347 0 .00953"/>
      <geometry>
        <cylinder length="0.01" radius="0.085"/>
      </geometry>
      <material name="darkgray">
        <color rgba=".2 .2 .2 1"/>
      </material>
    </visual>
    <collision>
      <origin rpy="0 0 0" xyz="0.0 0 0.0"/>
      <geometry>
        <sphere radius="0.001"/>
      </geometry>
    </collision>
    <inertial>
      <origin rpy="0 0 0" xyz="0 0 0"/>
      <mass value="0.0001"/>
      <inertia ixx="1e-08" ixy="0" ixz="0" iyy="1e-08" iyz="0" izz="1e-08"/>
    </inertial>
  </link>

  <link name="display">
    <visual>
      <origin rpy="0.2617993877991494 0 0" xyz="0 0 0"/>
      <geometry>
        <box size="0.218 0.16 0.001"/>
      </geometry>
      <material name="black">
        <color rgba="0 0 0 1"/>
      </material>
    </visual>
    <inertial>
      <origin rpy="0 0 0" xyz="0 0 0"/>
      <mass value="0.0001"/>
      <inertia ixx="1e-08" ixy="0" ixz="0" iyy="1e-08" iyz="0" izz="1e-08"/>
    </inertial>
  </link>


  <joint name="root_joint" type="floating">
    <origin rpy="0 0 0" xyz="0 0 0"/>
    <parent link="world"/>
    <child link="base"/>
    <limit effort="50000" lower="-3.01" upper="3.01" velocity="10000"/>
  </joint>

  <joint name="torso_t0" type="fixed">
    <origin rpy="0 0 0" xyz="0 0 0"/>
    <parent link="base"/>
    <child link="torso"/>
    <limit effort="50000" lower="-3.01" upper="3.01" velocity="10000"/>
  </joint>

  <joint name="pedestal_fixed" type="fixed">
    <origin rpy="0 0 0" xyz="0.0 0.0 0.0"/>
    <parent link="torso"/>
    <child link="pedestal"/>
  </joint>

  <joint name="head_pan" type="revolute">
    <origin rpy="0 0 0" xyz="0.06 0 0.686"/>
    <axis xyz="0 0 1"/>
    <parent link="torso"/>
    <child link="head"/>
    <limit effort="50000" lower="-1.57079632679" upper="1.57079632679" velocity="10000"/>
    <dynamics damping="0.7" friction="0.0"/>
  </joint>

  <joint name="head_nod" type="fixed">
    <origin rpy="1.75057 0 1.57079632679" xyz=".1227 0 0"/>
    <parent link="head"/>
    <child link="screen"/>
  </joint>

  <joint name="display_joint" type="fixed">
    <origin rpy="0 0 0" xyz="0.0 -0.016 0.0"/>
    <parent link="screen"/>
    <child link="display"/>
  </joint>
  <joint name="sonar_s0" type="fixed">
    <origin rpy="0 0 0" xyz="0.0947 0 .817"/>
    <axis xyz="0 0 1"/>
    <parent link="torso"/>
    <child link="sonar_ring"/>
  </joint>

</robot>
