<?xml version="1.0"?>

<robot name="baxter_right_arm">

  <link name="world" />
  <link name="right_arm_root" />


  <!-- Base link: Fixed -->
  <link name="right_arm_mount">
    <inertial>
      <origin rpy="0 0 0" xyz="0 0 0"/>
      <mass value="0.0001"/>
      <inertia ixx="1e-08" ixy="0" ixz="0" iyy="1e-08" iyz="0" izz="1e-08"/>
    </inertial>
  </link>

  <!-- Link 0 (moved by S0) -->
  <link name="right_upper_shoulder">
    <visual>
      <origin rpy="0 0 0" xyz="0 0 0"/>
      <geometry>
        <mesh filename="/home/ana/Research/commonData/robots/baxter/meshes/upper_shoulder/S0.DAE"/>
      </geometry>
      <material name="darkred">
        <color rgba=".5 .1 .1 1"/>
      </material>
    </visual>
    <collision>
      <origin rpy="0 0 0" xyz="0 0 0.1361"/>
      <geometry>
        <cylinder length="0.2722" radius="0.06"/>
      </geometry>
    </collision>
    <inertial>
      <origin rpy="0 0 0" xyz="0.01783 0.00086 0.19127"/>
      <mass value="5.70044"/>
      <inertia ixx="0.04709102262" ixy="0.00012787556" ixz="0.00614870039" iyy="0.03766976455" iyz="0.00078086899" izz="0.03595988478"/>
    </inertial>
  </link>

  <!-- Link 1 (moved by S1) -->
  <link name="right_lower_shoulder">
    <visual>
      <origin rpy="0 0 0" xyz="0 0 0"/>
      <geometry>
        <mesh filename="/home/ana/Research/commonData/robots/baxter/meshes/lower_shoulder/S1.DAE"/>
      </geometry>
      <material name="darkred">
        <color rgba=".5 .1 .1 1"/>
      </material>
    </visual>
    <collision>
      <origin rpy="0 0 0" xyz="0 0 0"/>
      <geometry>
        <cylinder length="0.12" radius="0.06"/>
      </geometry>
    </collision>
    <inertial>
      <origin rpy="0 0 0" xyz="0.06845 0.00269 -0.00529"/>
      <mass value="3.22698"/>
      <inertia ixx="0.01175209419" ixy="-0.00030096398" ixz="0.00207675762" iyy="0.0278859752" iyz="-0.00018821993" izz="0.02078749298"/>
    </inertial>
  </link>

  <!-- Link 2 (moved by E0) -->
  <link name="right_upper_elbow">
    <visual>
      <origin rpy="0 0 0" xyz="0 0 0"/>
      <geometry>
        <mesh filename="/home/ana/Research/commonData/robots/baxter/meshes/upper_elbow/E0.DAE"/>
      </geometry>
      <material name="darkred">
        <color rgba=".5 .1 .1 1"/>
      </material>
    </visual>

    <!-- Yes, 2 meshes for collision -->
    <collision>
      <origin rpy="0 0 0" xyz="0 0 -0.0535"/>
      <geometry>
        <cylinder length="0.107" radius="0.06"/>
      </geometry>
    </collision> 
    <collision>
      <origin rpy="0 0 0" xyz="0 0 0.1365"/>
      <geometry>
        <cylinder length="0.273" radius="0.06"/>
      </geometry>
    </collision>

    <inertial>
      <origin rpy="0 0 0" xyz="-0.00276 0.00132 0.18086"/>
      <mass value="4.31272"/>
      <inertia ixx="0.02661733557" ixy="0.00029270634" ixz="0.00392189887" iyy="0.02844355207" iyz="0.0010838933" izz="0.01248008322"/>
    </inertial>
  </link>


  <!-- Link 3 (moved by E1) -->
  <link name="right_lower_elbow">
    <visual>
      <origin rpy="0 0 0" xyz="0 0 0"/>
      <geometry>
        <mesh filename="/home/ana/Research/commonData/robots/baxter/meshes/lower_elbow/E1.DAE"/>
      </geometry>
      <material name="darkred">
        <color rgba=".5 .1 .1 1"/>
      </material>
    </visual>
    <collision>
      <origin rpy="0 0 0" xyz="0.0 0.0 0.0"/>
      <geometry>
        <cylinder length="0.10" radius="0.06"/>
      </geometry>
    </collision>
    <inertial>
      <origin rpy="0 0 0" xyz="0.02611 0.00159 -0.01117"/>
      <mass value="2.07206"/>
      <inertia ixx="0.00711582686" ixy="0.00036036173" ixz="0.0007459496" iyy="0.01318227876" iyz="-0.00019663418" izz="0.00926852064"/>
    </inertial>
  </link>

  <!-- Link 4 (moved by W0) -->
  <link name="right_upper_forearm">
    <visual>
      <origin rpy="0 0 0" xyz="0 0 0"/>
      <geometry>
        <mesh filename="/home/ana/Research/commonData/robots/baxter/meshes/upper_forearm/W0.DAE"/>
      </geometry>
      <material name="darkred">
        <color rgba=".5 .1 .1 1"/>
      </material>
    </visual>

    <!-- Yes, two meshes for collision -->
    <collision>
      <origin rpy="0 0 0" xyz="0 0 -0.044"/>
      <geometry>
        <cylinder length="0.088" radius="0.06"/>
      </geometry>
    </collision>
    <collision>
      <origin rpy="0 0 0" xyz="0 0 0.136"/>
      <geometry>
        <cylinder length="0.272" radius="0.06"/>
      </geometry>
    </collision>

    <inertial>
      <origin rpy="0 0 0" xyz="-0.00168 0.0046 0.13952"/>
      <mass value="2.24665"/>
      <inertia ixx="0.01667742825" ixy="0.00018403705" ixz="0.00018657629" iyy="0.01675457264" iyz="-0.00064732352" izz="0.0037463115"/>
    </inertial>
  </link>

  <!-- Link 5 (moved by W1) -->
  <link name="right_lower_forearm">
    <visual>
      <origin rpy="0 0 0" xyz="0 0 0"/>
      <geometry>
        <mesh filename="/home/ana/Research/commonData/robots/baxter/meshes/lower_forearm/W1.DAE"/>
      </geometry>
      <material name="darkred">
        <color rgba=".5 .1 .1 1"/>
      </material>
    </visual>
    <collision>
      <origin rpy="0 0 0" xyz="0 0 0"/>
      <geometry>
        <cylinder length="0.10" radius="0.06"/>
      </geometry>
    </collision>
    <inertial>
      <origin rpy="0 0 0" xyz="0.06041 0.00697 0.006"/>
      <mass value="1.60979"/>
      <inertia ixx="0.00387607152" ixy="-0.00044384784" ixz="-0.00021115038" iyy="0.00700537914" iyz="0.00015348067" izz="0.0055275524"/>
    </inertial>
  </link>

  <!-- Link 6 (moved by W2) -->
  <link name="right_wrist">
    <visual>
      <origin rpy="0 0 0" xyz="0 0 0"/>
      <geometry>
        <mesh filename="/home/ana/Research/commonData/robots/baxter/meshes/wrist/W2.DAE"/>
      </geometry>
      <material name="lightgrey">
        <color rgba=".1 .1 .1 1"/>
      </material>
    </visual>
    <collision>
      <origin rpy="0 0 0" xyz="0 0 0"/>
      <geometry>
        <cylinder length="0.165" radius="0.06"/>
      </geometry>
    </collision>
    <inertial>
      <origin rpy="0 0 0" xyz="0.00198 0.00125 0.01855"/>
      <mass value="0.35093"/>
      <inertia ixx="0.00025289155" ixy="0.00000575311" ixz="-0.00000159345" iyy="0.0002688601" iyz="-0.00000519818" izz="0.0003074118"/>
    </inertial>
  </link>

  <link name="right_hand">
    <collision>
      <origin rpy="0 0 0" xyz="0 0 -0.0232"/>
      <geometry>
        <cylinder length="0.0464" radius="0.04"/>
      </geometry>
    </collision>
    <inertial>
      <origin rpy="0 0 0" xyz="0.01093 0.00042 -0.01532"/>
      <mass value="0.19125"/>
      <inertia ixx="0.00017588" ixy="0.00000147073" ixz="0.0000243633" iyy="0.00021166377" iyz="0.00000172689" izz="0.00023745397"/>
    </inertial>
  </link>


  <!-- JOINTS -->

  <joint name="right_arm_root_joint" type="floating">
    <origin rpy="0 0 0" xyz="0 0 0"/>
    <parent link="world"/>
    <child link="right_arm_root"/>
  </joint>

  <joint name="right_torso_arm_mount" type="fixed">
    <origin rpy="0 0 -0.7854" xyz="0.024645 -0.219645 0.118588"/>
    <parent link="right_arm_root"/>
    <child link="right_arm_mount"/>
  </joint>

  <!-- Joint Right S0 -->
  <joint name="right_s0" type="revolute">
    <origin rpy="0 0 0" xyz="0.055695 0 0.011038"/>
    <axis xyz="0 0 1"/>
    <parent link="right_arm_mount"/>
    <child link="right_upper_shoulder"/>
    <limit effort="50.0" lower="-1.70167993878" upper="1.70167993878" velocity="1.5"/>
    <dynamics damping="0.7" friction="0.0"/>
  </joint>

  <!-- Joint Right S1 -->
  <joint name="right_s1" type="revolute">
    <origin rpy="-1.57079632679 0 0" xyz="0.069 0 0.27035"/>
    <axis xyz="0 0 1"/>
    <parent link="right_upper_shoulder"/>
    <child link="right_lower_shoulder"/>
    <limit effort="100.0" lower="-2.147" upper="1.047" velocity="1.5"/>
    <dynamics damping="0.7" friction="0.0"/>
  </joint>

  <!-- Joint Right E0 -->
  <joint name="right_e0" type="revolute">
    <origin rpy="1.57079632679 0 1.57079632679" xyz="0.102 0 0"/>
    <axis xyz="0 0 1"/>
    <parent link="right_lower_shoulder"/>
    <child link="right_upper_elbow"/>
    <limit effort="50.0" lower="-3.05417993878" upper="3.05417993878" velocity="1.5"/>
    <dynamics damping="0.7" friction="0.0"/>
  </joint>

  <!-- Right E1 -->
  <joint name="right_e1" type="revolute">
    <origin rpy="-1.57079632679 -1.57079632679 0" xyz="0.069 0 0.26242"/>
    <axis xyz="0 0 1"/>
    <parent link="right_upper_elbow"/>
    <child link="right_lower_elbow"/>
    <limit effort="50.0" lower="-0.05" upper="2.618" velocity="1.5"/>
    <dynamics damping="0.7" friction="0.0"/>
  </joint>

  <!-- Right W0 -->
  <joint name="right_w0" type="revolute">
    <origin rpy="1.57079632679 0 1.57079632679" xyz="0.10359 0 0"/>
    <axis xyz="0 0 1"/>
    <parent link="right_lower_elbow"/>
    <child link="right_upper_forearm"/>
    <limit effort="15.0" lower="-3.059" upper="3.059" velocity="4.0"/>
    <dynamics damping="0.7" friction="0.0"/>
  </joint>


  <!-- Right W1 -->
  <joint name="right_w1" type="revolute">
    <origin rpy="-1.57079632679 -1.57079632679 0" xyz="0.01 0 0.2707"/>
    <axis xyz="0 0 1"/>
    <parent link="right_upper_forearm"/>
    <child link="right_lower_forearm"/>
    <limit effort="15.0" lower="-1.57079632679" upper="2.094" velocity="4.0"/>
    <dynamics damping="0.7" friction="0.0"/>
  </joint>

  <!-- Right W2 -->
  <joint name="right_w2" type="revolute">
    <origin rpy="1.57079632679 0 1.57079632679" xyz="0.115975 0 0"/>
    <axis xyz="0 0 1"/>
    <parent link="right_lower_forearm"/>
    <child link="right_wrist"/>
    <limit effort="15.0" lower="-3.059" upper="3.059" velocity="4.0"/>
    <dynamics damping="0.7" friction="0.0"/>
  </joint>

  <!-- Right hand base -->
  <joint name="right_hand" type="fixed">
    <origin rpy="0 0 0" xyz="0 0 0.11355"/>
    <axis xyz="0 0 1"/>
    <parent link="right_wrist"/>
    <child link="right_hand"/>
    <dynamics damping="0.7" friction="0.0"/>
  </joint>

<!--

  <link name="right_gripper_base">
    <visual>
      <origin rpy="0 0 0" xyz="0 0 -0.02"/>
      <geometry>
        <box size="0.025 0.075 0.035"/>
      </geometry>
      <material name="darkred">
        <color rgba=".5 .1 .1 1"/>
      </material>
    </visual>
    <inertial>
      <origin rpy="0 0 0" xyz="0.000000 0.000000 0.000000"/>
      <mass value="0.0001"/>
      <inertia ixx="1e-08" ixy="0" ixz="0" iyy="1e-08" iyz="0" izz="1e-08"/>
    </inertial>
  </link>

  <link name="right_gripper">
    <visual>
      <origin rpy="0 0 0" xyz="0 0 0"/>
      <geometry>
        <box size="0.01 0.01 0.01"/>
      </geometry>
      <material name="black">
        <color rgba="0 0 0 1"/>
      </material>
    </visual>
    <inertial>
      <origin rpy="0 0 0" xyz="0.000000 0.000000 0.000000"/>
      <mass value="0.0001"/>
      <inertia ixx="1e-08" ixy="0" ixz="0" iyy="1e-08" iyz="0" izz="1e-08"/>
    </inertial>
  </link>

  <joint name="right_gripper_base" type="fixed">
    <origin rpy="0 0 0" xyz="0 0 0"/>
    <parent link="right_hand"/>
    <child link="right_gripper_base"/>
  </joint>
  <joint name="right_endpoint" type="fixed">
    <origin rpy="0 0 0" xyz="0.0 0 0.025"/>
    <parent link="right_gripper_base"/>
    <child link="right_gripper"/>
  </joint>


-->

</robot>
