<robot name="huboRightHand">

   <!-- -->			
   <link name="world" />


    <link name="rightPalm">
        <inertial>
            <origin rpy="-0 0 -0" xyz="0.0052673447224298202 0.00165481505247564 -0.047696718384656701" />
            <mass value="0.474006924726537" />
            <inertia ixx="0.000397832341494148" ixy="-2.6284743947387800e-06" ixz="-1.84132721696329E-05" iyy="0.000310585574870465" iyz="5.7461134045111800e-06" izz="0.000251799615334244" />
        </inertial>
        <visual>
            <origin rpy="-0 0 -0" xyz="0 -0 0" />
            <geometry>
                <mesh filename="../meshes/convhull_RWR_merged.stl" />
            </geometry>
            <material name="">
                <color rgba="0.752941176470588 0.752941176470588 0.752941176470588 1" />
            </material>
        </visual>
        <collision>
            <origin rpy="-0 0 -0" xyz="0 -0 0" />
            <geometry>
                <mesh filename="../meshes/convhull_RWR_merged.stl" />
            </geometry>
        </collision>

    </link>
    <link name="Body_RF11">
        <inertial>
            <origin rpy="-0 0 -0" xyz="4.0808242114456797E-06 0.010365457906814099 -0.022357214658374602" />
            <mass value="0.0209635645691505" />
            <inertia ixx="5.79877083007342E-06" ixy="3.6189665497296299e-09" ixz="2.45166522675331E-07" iyy="6.02432212425641E-06" iyz="-1.2116739475733400e-09" izz="1.78245355770108E-06" />
        </inertial>
        <visual>
            <origin rpy="-0 0 -0" xyz="0 -0 0" />
            <geometry>
                <mesh filename="../meshes/convhull_RF1.stl" />
            </geometry>
            <material name="">
                <color rgba="0.752941176470588 0.752941176470588 0.752941176470588 1" />
            </material>
        </visual>
        <collision>
            <origin rpy="-0 0 -0" xyz="0 -0 0" />
            <geometry>
                <mesh filename="../meshes/convhull_RF1.stl" />
            </geometry>
        </collision>
    </link>
    <link name="Body_RF12">
        <inertial>
            <origin rpy="-0 0 -0" xyz="0.00013094697176082399 -0.00022677183338540299 -0.0135375370531412" />
            <mass value="0.0121177256078384" />
            <inertia ixx="2.50372945957958E-06" ixy="2.3280589150823100e-09" ixz="5.14105106916585E-08" iyy="2.26813369660349E-06" iyz="4.9296412483752203e-09" izz="1.22101156825522E-06" />
        </inertial>
        <visual>
            <origin rpy="-0 0 -0" xyz="0 -0 0" />
            <geometry>
                <mesh filename="../meshes/convhull_RF2.stl" />
            </geometry>
            <material name="">
                <color rgba="0.752941176470588 0.752941176470588 0.752941176470588 1" />
            </material>
        </visual>
        <collision>
            <origin rpy="-0 0 -0" xyz="0 -0 0" />
            <geometry>
                <mesh filename="../meshes/convhull_RF2.stl" />
            </geometry>
        </collision>
    </link>
    <link name="Body_RF13">
        <inertial>
            <origin rpy="-0 0 -0" xyz="0.00016938613030157901 -0.00035689841965924602 -0.016316521975207599" />
            <mass value="0.0163435127658012" />
            <inertia ixx="2.35338373719888E-06" ixy="4.4210418009567002e-09" ixz="1.38024261681812E-07" iyy="2.40973096927305E-06" iyz="2.8221502007736200e-08" izz="9.69758896639509E-07" />
        </inertial>
        <visual>
            <origin rpy="-0 0 -0" xyz="0 -0 0" />
            <geometry>
                <mesh filename="../meshes/convhull_RF3.stl" />
            </geometry>
            <material name="">
                <color rgba="0.752941176470588 0.752941176470588 0.752941176470588 1" />
            </material>
        </visual>
        <collision>
            <origin rpy="-0 0 -0" xyz="0 -0 0" />
            <geometry>
                <mesh filename="../meshes/convhull_RF3.stl" />
            </geometry>
        </collision>
    </link>
 
 
    <link name="Body_RF21">
        <inertial>
            <origin rpy="-0 0 -0" xyz="4.0808242114456797E-06 0.010365457906814099 -0.022357214658374602" />
            <mass value="0.0209635645691505" />
            <inertia ixx="5.79877083007342E-06" ixy="3.6189665497296299e-09" ixz="2.45166522675331E-07" iyy="6.02432212425641E-06" iyz="-1.2116739475733400e-09" izz="1.78245355770108E-06" />
        </inertial>
        <visual>
            <origin rpy="-0 0 -0" xyz="0 -0 0" />
            <geometry>
                <mesh filename="../meshes/convhull_RF1.stl" />
            </geometry>
            <material name="">
                <color rgba="0.752941176470588 0.752941176470588 0.752941176470588 1" />
            </material>
        </visual>
        <collision>
            <origin rpy="-0 0 -0" xyz="0 -0 0" />
            <geometry>
                <mesh filename="../meshes/convhull_RF1.stl" />
            </geometry>
        </collision>
    </link>
    <link name="Body_RF22">
        <inertial>
            <origin rpy="-0 0 -0" xyz="0.00013094697176082399 -0.00022677183338540299 -0.0135375370531412" />
            <mass value="0.0121177256078384" />
            <inertia ixx="2.50372945957958E-06" ixy="2.3280589150823100e-09" ixz="5.14105106916585E-08" iyy="2.26813369660349E-06" iyz="4.9296412483752203e-09" izz="1.22101156825522E-06" />
        </inertial>
        <visual>
            <origin rpy="-0 0 -0" xyz="0 -0 0" />
            <geometry>
                <mesh filename="../meshes/convhull_RF2.stl" />
            </geometry>
            <material name="">
                <color rgba="0.752941176470588 0.752941176470588 0.752941176470588 1" />
            </material>
        </visual>
        <collision>
            <origin rpy="-0 0 -0" xyz="0 -0 0" />
            <geometry>
                <mesh filename="../meshes/convhull_RF2.stl" />
            </geometry>
        </collision>
    </link>
    <link name="Body_RF23">
        <inertial>
            <origin rpy="-0 0 -0" xyz="0.00016938613030157901 -0.00035689841965924602 -0.016316521975207599" />
            <mass value="0.0163435127658012" />
            <inertia ixx="2.35338373719888E-06" ixy="4.4210418009567002e-09" ixz="1.38024261681812E-07" iyy="2.40973096927305E-06" iyz="2.8221502007736200e-08" izz="9.69758896639509E-07" />
        </inertial>
        <visual>
            <origin rpy="-0 0 -0" xyz="0 -0 0" />
            <geometry>
                <mesh filename="../meshes/convhull_RF3.stl" />
            </geometry>
            <material name="">
                <color rgba="0.752941176470588 0.752941176470588 0.752941176470588 1" />
            </material>
        </visual>
        <collision>
            <origin rpy="-0 0 -0" xyz="0 -0 0" />
            <geometry>
                <mesh filename="../meshes/convhull_RF3.stl" />
            </geometry>
        </collision>
    </link>
    <link name="Body_RF31">
        <inertial>
            <origin rpy="-0 0 -0" xyz="4.0808242114456797E-06 0.010365457906814099 -0.022357214658374602" />
            <mass value="0.0209635645691505" />
            <inertia ixx="5.79877083007342E-06" ixy="3.6189665497296299e-09" ixz="2.45166522675331E-07" iyy="6.02432212425641E-06" iyz="-1.2116739475733400e-09" izz="1.78245355770108E-06" />
        </inertial>
        <visual>
            <origin rpy="-0 0 -0" xyz="0 -0 0" />
            <geometry>
                <mesh filename="../meshes/convhull_RF1.stl" />
            </geometry>
            <material name="">
                <color rgba="0.752941176470588 0.752941176470588 0.752941176470588 1" />
            </material>
        </visual>
        <collision>
            <origin rpy="-0 0 -0" xyz="0 -0 0" />
            <geometry>
                <mesh filename="../meshes/convhull_RF1.stl" />
            </geometry>
        </collision>
    </link>
    <link name="Body_RF32">
        <inertial>
            <origin rpy="-0 0 -0" xyz="0.00013094697176082399 -0.00022677183338540299 -0.0135375370531412" />
            <mass value="0.0121177256078384" />
            <inertia ixx="2.50372945957958E-06" ixy="2.3280589150823100e-09" ixz="5.14105106916585E-08" iyy="2.26813369660349E-06" iyz="4.9296412483752203e-09" izz="1.22101156825522E-06" />
        </inertial>
        <visual>
            <origin rpy="-0 0 -0" xyz="0 -0 0" />
            <geometry>
                <mesh filename="../meshes/convhull_RF2.stl" />
            </geometry>
            <material name="">
                <color rgba="0.752941176470588 0.752941176470588 0.752941176470588 1" />
            </material>
        </visual>
        <collision>
            <origin rpy="-0 0 -0" xyz="0 -0 0" />
            <geometry>
                <mesh filename="../meshes/convhull_RF2.stl" />
            </geometry>
        </collision>
    </link>
    <link name="Body_RF33">
        <inertial>
            <origin rpy="-0 0 -0" xyz="0.00016938613030157901 -0.00035689841965924602 -0.016316521975207599" />
            <mass value="0.0163435127658012" />
            <inertia ixx="2.35338373719888E-06" ixy="4.4210418009567002e-09" ixz="1.38024261681812E-07" iyy="2.40973096927305E-06" iyz="2.8221502007736200e-08" izz="9.69758896639509E-07" />
        </inertial>
        <visual>
            <origin rpy="-0 0 -0" xyz="0 -0 0" />
            <geometry>
                <mesh filename="../meshes/convhull_RF3.stl" />
            </geometry>
            <material name="">
                <color rgba="0.752941176470588 0.752941176470588 0.752941176470588 1" />
            </material>
        </visual>
        <collision>
            <origin rpy="-0 0 -0" xyz="0 -0 0" />
            <geometry>
                <mesh filename="../meshes/convhull_RF3.stl" />
            </geometry>
        </collision>
    </link>

    <link name="Body_RF41">
        <inertial>
            <origin rpy="-0 0 -0" xyz="4.0808242114456797E-06 0.010365457906814099 -0.022357214658374602" />
            <mass value="0.0209635645691505" />
            <inertia ixx="5.79877083007342E-06" ixy="3.6189665497296299e-09" ixz="2.45166522675331E-07" iyy="6.02432212425641E-06" iyz="-1.2116739475733400e-09" izz="1.78245355770108E-06" />
        </inertial>
        <visual>
            <origin rpy="-0 0 -0" xyz="0 -0 0" />
            <geometry>
                <mesh filename="../meshes/convhull_RF1.stl" />
            </geometry>
            <material name="">
                <color rgba="0.752941176470588 0.752941176470588 0.752941176470588 1" />
            </material>
        </visual>
        <collision>
            <origin rpy="-0 0 -0" xyz="0 -0 0" />
            <geometry>
                <mesh filename="../meshes/convhull_RF1.stl" />
            </geometry>
        </collision>
    </link>
    <link name="Body_RF42">
        <inertial>
            <origin rpy="-0 0 -0" xyz="0.00013094697176082399 -0.00022677183338540299 -0.0135375370531412" />
            <mass value="0.0121177256078384" />
            <inertia ixx="2.50372945957958E-06" ixy="2.3280589150823100e-09" ixz="5.14105106916585E-08" iyy="2.26813369660349E-06" iyz="4.9296412483752203e-09" izz="1.22101156825522E-06" />
        </inertial>
        <visual>
            <origin rpy="-0 0 -0" xyz="0 -0 0" />
            <geometry>
                <mesh filename="../meshes/convhull_RF2.stl" />
            </geometry>
            <material name="">
                <color rgba="0.752941176470588 0.752941176470588 0.752941176470588 1" />
            </material>
        </visual>
        <collision>
            <origin rpy="-0 0 -0" xyz="0 -0 0" />
            <geometry>
                <mesh filename="../meshes/convhull_RF2.stl" />
            </geometry>
        </collision>
    </link>
    <link name="Body_RF43">
        <inertial>
            <origin rpy="-0 0 -0" xyz="0.00016938613030157901 -0.00035689841965924602 -0.016316521975207599" />
            <mass value="0.0163435127658012" />
            <inertia ixx="2.35338373719888E-06" ixy="4.4210418009567002e-09" ixz="1.38024261681812E-07" iyy="2.40973096927305E-06" iyz="2.8221502007736200e-08" izz="9.69758896639509E-07" />
        </inertial>
        <visual>
            <origin rpy="-0 0 -0" xyz="0 -0 0" />
            <geometry>
                <mesh filename="../meshes/convhull_RF3.stl" />
            </geometry>
            <material name="">
                <color rgba="0.752941176470588 0.752941176470588 0.752941176470588 1" />
            </material>
        </visual>
        <collision>
            <origin rpy="-0 0 -0" xyz="0 -0 0" />
            <geometry>
                <mesh filename="../meshes/convhull_RF3.stl" />
            </geometry>
        </collision>
    </link>

    <joint name="RWR_dummy" type="floating">
        <origin rpy="0 0 0" xyz="0 0 0" />
        <parent link="world" />
        <child link="rightPalm" />
    </joint>
    <joint name="RF11" type="revolute">
        <origin rpy="-0 0 -0" xyz="0.0230 0.0120 -0.0755" />
        <parent link="rightPalm" />
        <child link="Body_RF11" />
        <axis xyz="0 1 0" />
        <limit effort="10.0" lower="-1.5" upper=".1" velocity="2.0" />
    </joint>
    <joint name="RF12" type="revolute">
        <origin rpy="-0 0 -0" xyz="-0.0020 0.0105 -0.0420" />
        <parent link="Body_RF11" />
        <child link="Body_RF12" />
        <axis xyz="0 1 0" />
        <limit effort="10.0" lower="0.1" upper="1.5" velocity="2.0" />
    </joint>
    <joint name="RF13" type="revolute">
        <origin rpy="-0 0 -0" xyz="-0.0014 -0 -0.0300" />
        <parent link="Body_RF12" />
        <child link="Body_RF13" />
        <axis xyz="0 1 0" />
        <limit effort="10.0" lower="0.1" upper="1.5" velocity="2.0" />
    </joint>
 
    <joint name="RF21" type="revolute">
        <origin rpy="-0 0 -0" xyz="0.0230 -0.0330 -0.0755" />
        <parent link="rightPalm" />
        <child link="Body_RF21" />
        <axis xyz="0 1 0" />
        <limit effort="10.0" lower="-1.5" upper=".1" velocity="2.0" />
    </joint>
    <joint name="RF22" type="revolute">
        <origin rpy="-0 0 -0" xyz="-0.0020 0.0105 -0.0420" />
        <parent link="Body_RF21" />
        <child link="Body_RF22" />
        <axis xyz="0 1 0" />
        <limit effort="10.0" lower="0.1" upper="1.5" velocity="2.0" />
    </joint>
    <joint name="RF23" type="revolute">
        <origin rpy="-0 0 -0" xyz="-0.0014 -0 -0.0300" />
        <parent link="Body_RF22" />
        <child link="Body_RF23" />
        <axis xyz="0 1 0" />
        <limit effort="10.0" lower="0.1" upper="1.5" velocity="2.0" />
    </joint>

    <joint name="RF31" type="revolute">
        <origin rpy="-0 0 -3.141592653589" xyz="-0.023 0.0105 -0.0755" />
        <parent link="rightPalm" />
        <child link="Body_RF31" />
        <axis xyz="0 1 0" />
        <limit effort="10.0" lower="-1.5" upper=".1" velocity="2.0" />
    </joint>
    <joint name="RF32" type="revolute">
        <origin rpy="0 0 0" xyz="-0.0020 0.0105 -0.0420" />
        <parent link="Body_RF31" />
        <child link="Body_RF32" />
        <axis xyz="0 1 0" />
        <limit effort="10.0" lower="-0.1" upper="1.5" velocity="2.0" />
    </joint>
    <joint name="RF33" type="revolute">
        <origin rpy="-0 0 -0" xyz="-0.0014 -0 -0.0300" />
        <parent link="Body_RF32" />
        <child link="Body_RF33" />
        <axis xyz="0 1 0" />
        <limit effort="10.0" lower="-0.1" upper="1.5" velocity="2.0" />
    </joint>
    <joint name="RF41" type="revolute">
        <origin rpy="-0 0 -3.141592653589" xyz="-0.0230 0.0555 -0.0755" />
        <parent link="rightPalm" />
        <child link="Body_RF41" />
        <axis xyz="0 1 0" />
        <limit effort="10.0" lower="-1.5" upper=".1" velocity="2.0" />
    </joint>
    <joint name="RF42" type="revolute">
        <origin rpy="-0 0 -0" xyz="-0.002 0.0105 -0.0420" />
        <parent link="Body_RF41" />
        <child link="Body_RF42" />
        <axis xyz="0 1 0" />
        <limit effort="10.0" lower="-0.1" upper="1.5" velocity="2.0" />
    </joint>
    <joint name="RF43" type="revolute">
        <origin rpy="-0 0 -0" xyz="-0.0014 -0 -0.0300" />
        <parent link="Body_RF42" />
        <child link="Body_RF43" />
        <axis xyz="0 1 0" />
        <limit effort="10.0" lower="-0.1" upper="1.5" velocity="2.0" />
    </joint>
</robot>
